


weight=1
embed_into_distance=10

unacceptable_target_blocks=flowing_water,water,flowing_lava,lava,Natura:Cloud,red_mushroom_block,brown_mushroom_block,planks,cobblestone,end_stone,purpur_block,iron_bars,purpur_slab,purpur_pillar,netherrack,soul_sand,quartz_ore

dimensions=33,13,13
allowable_overhang=2
max_leveling=10
leveling_buffer=-1
preserve_water=0
preserve_lava=0
preserve_plants=1


rule1=0,100,preserveBlock
rule2=0,100,techguns:sand_hard,techguns:sand_hard,preserveBlock
rule3=0,75,techguns:sand_hard,preserveBlock
rule4=1,75,techguns:sand_hard
rule5=1,75,techguns:sand_hard,techguns:sand_hard,techguns:slimy
rule6=0,100,techguns:sand_hard,techguns:sand_hard,techguns:sand_hard,techguns:slimy
rule7=1,75,techguns:sand_hard,techguns:sand_hard,techguns:sand_hard,techguns:slimy
rule8=0,100,techguns:sand_hard,techguns:sand_hard,techguns:sand_hard,techguns:sand_hard,techguns:slimy
rule9=1,75,techguns:sand_hard,techguns:sand_hard,techguns:sand_hard,techguns:sand_hard,techguns:sand_hard,techguns:sand_hard,techguns:sand_hard,techguns:sand_hard,techguns:sand_hard,techguns:sand_hard,techguns:sand_hard,techguns:slimy
rule10=0,100,techguns:sand_hard,techguns:sand_hard,techguns:sand_hard,techguns:sand_hard,techguns:sand_hard,techguns:sand_hard,techguns:sand_hard,techguns:sand_hard,techguns:sand_hard,techguns:sand_hard,techguns:sand_hard,techguns:sand_hard,techguns:slimy
rule11=1,75,techguns:sand_hard,techguns:sand_hard,techguns:sand_hard,techguns:sand_hard,techguns:sand_hard,techguns:sand_hard,techguns:sand_hard,techguns:sand_hard,techguns:sand_hard,techguns:sand_hard,techguns:sand_hard,techguns:sand_hard,techguns:sand_hard,techguns:sand_hard,techguns:sand_hard,techguns:sand_hard,techguns:sand_hard,techguns:sand_hard,techguns:sand_hard,techguns:slimy
rule12=0,100,techguns:sand_hard,techguns:sand_hard,techguns:sand_hard,techguns:sand_hard,techguns:sand_hard,techguns:sand_hard,techguns:sand_hard,techguns:sand_hard,techguns:sand_hard,techguns:sand_hard,techguns:sand_hard,techguns:sand_hard,techguns:sand_hard,techguns:sand_hard,techguns:sand_hard,techguns:sand_hard,techguns:sand_hard,techguns:sand_hard,techguns:sand_hard,techguns:sand_hard,techguns:slimy
rule13=1,75,techguns:sand_hard,techguns:sand_hard,techguns:sand_hard,techguns:sand_hard,techguns:sand_hard,techguns:sand_hard,techguns:sand_hard,techguns:sand_hard,techguns:sand_hard,techguns:sand_hard,techguns:sand_hard,techguns:sand_hard,techguns:sand_hard,techguns:slimy
rule14=0,100,techguns:sand_hard,techguns:sand_hard,techguns:sand_hard,techguns:sand_hard,techguns:sand_hard,techguns:sand_hard,techguns:sand_hard,techguns:sand_hard,techguns:sand_hard,techguns:sand_hard,techguns:sand_hard,techguns:sand_hard,techguns:sand_hard,techguns:sand_hard,techguns:slimy
rule15=1,100,techguns:sand_hard,techguns:sand_hard,techguns:sand_hard,techguns:sand_hard,techguns:sand_hard,techguns:sand_hard,techguns:sand_hard,techguns:sand_hard,techguns:sand_hard,techguns:sand_hard,techguns:sand_hard,techguns:sand_hard,techguns:sand_hard,techguns:sand_hard,techguns:sand_hard,techguns:slimy
rule16=0,100,preserveBlock
rule17=1,100,techguns:sand_hard,techguns:sand_hard,MobSpawner:techguns:alienbug

layer
1,2,2,2,2,2,2,2,2,2,2,2,1
2,2,2,2,2,2,2,2,2,2,2,2,2
2,2,2,2,2,2,2,2,2,2,2,2,2
2,2,2,2,2,2,2,2,2,2,2,2,2
2,2,2,2,2,2,2,2,2,2,2,2,2
2,2,2,2,2,2,2,2,2,2,2,2,2
2,2,2,2,2,2,2,2,2,2,2,2,2
2,2,2,2,2,2,2,2,2,2,2,2,2
2,2,2,2,2,2,2,2,2,2,2,2,2
2,2,2,2,2,2,2,2,2,2,2,2,2
2,2,2,2,2,2,2,2,2,2,2,2,2
2,2,2,2,2,2,2,2,2,2,2,2,2
1,2,2,2,2,2,2,2,2,2,2,2,1
endlayer

layer
16,3,3,3,3,3,3,3,3,3,3,3,16
3,3,2,2,2,2,2,2,2,2,2,3,3
3,2,2,2,2,2,2,2,2,2,2,2,3
3,2,2,2,2,2,2,2,2,2,2,2,3
3,2,2,2,2,2,2,2,2,2,2,2,3
3,2,2,2,2,2,2,2,2,2,2,2,3
3,2,2,2,2,2,17,2,2,2,2,2,3
3,2,2,2,2,2,2,2,2,2,2,2,3
3,2,2,2,2,2,2,2,2,2,2,2,3
3,2,2,2,2,2,2,2,2,2,2,2,3
3,2,2,2,2,2,2,2,2,2,2,2,3
3,3,2,2,2,2,2,2,2,2,2,3,3
16,3,3,3,3,3,3,3,3,3,3,3,16
endlayer

layer
16,4,4,4,4,4,4,4,4,4,4,4,16
4,4,2,2,2,2,2,2,2,2,2,4,4
4,2,2,2,2,2,2,2,2,2,2,2,4
4,2,2,2,2,2,2,2,2,2,2,2,4
4,2,2,2,2,2,2,2,2,2,2,2,4
4,2,2,2,2,2,2,2,2,2,2,2,4
4,2,2,2,2,2,17,2,2,2,2,2,4
4,2,2,2,2,2,2,2,2,2,2,2,4
4,2,2,2,2,2,2,2,2,2,2,2,4
4,2,2,2,2,2,2,2,2,2,2,2,4
4,2,2,2,2,2,2,2,2,2,2,2,4
4,4,2,2,2,2,2,2,2,2,2,4,4
16,4,4,4,4,4,4,4,4,4,4,4,16
endlayer

layer
16,4,4,4,4,4,4,4,4,4,4,4,16
4,4,2,2,2,2,2,2,2,2,2,4,4
4,2,2,2,2,2,2,2,2,2,2,2,4
4,2,2,2,2,2,2,2,2,2,2,2,4
4,2,2,2,2,2,2,2,2,2,2,2,4
4,2,2,2,2,2,2,2,2,2,2,2,4
4,2,2,2,2,2,17,2,2,2,2,2,4
4,2,2,2,2,2,2,2,2,2,2,2,4
4,2,2,2,2,2,2,2,2,2,2,2,4
4,2,2,2,2,2,2,2,2,2,2,2,4
4,2,2,2,2,2,2,2,2,2,2,2,4
4,4,2,2,2,2,2,2,2,2,2,4,4
16,4,4,4,4,4,4,4,4,4,4,4,16
endlayer

layer
16,4,4,4,4,4,4,4,4,4,4,4,16
4,4,2,2,2,2,2,2,2,2,2,4,4
4,2,2,2,2,2,2,2,2,2,2,2,4
4,2,2,2,2,2,2,2,2,2,2,2,4
4,2,2,2,2,2,2,2,2,2,2,2,4
4,2,2,2,2,2,2,2,2,2,2,2,4
4,2,2,2,2,2,17,2,2,2,2,2,4
4,2,2,2,2,2,2,2,2,2,2,2,4
4,2,2,2,2,2,2,2,2,2,2,2,4
4,2,2,2,2,2,2,2,2,2,2,2,4
4,2,2,2,2,2,2,2,2,2,2,2,4
4,4,2,2,2,2,2,2,2,2,2,4,4
16,4,4,4,4,4,4,4,4,4,4,4,16
endlayer

layer
16,4,4,4,4,4,4,4,4,4,4,4,16
4,4,3,3,3,3,3,3,3,3,3,4,4
4,3,3,2,2,2,2,2,2,2,3,3,4
4,3,2,2,2,2,2,2,2,2,2,3,4
4,3,2,2,2,2,2,2,2,2,2,3,4
4,3,2,2,2,2,2,2,2,2,2,3,4
4,3,2,2,2,2,17,2,2,2,2,3,4
4,3,2,2,2,2,2,2,2,2,2,3,4
4,3,2,2,2,2,2,2,2,2,2,3,4
4,3,2,2,2,2,2,2,2,2,2,3,4
4,3,3,2,2,2,2,2,2,2,3,3,4
4,4,3,3,3,3,3,3,3,3,3,4,4
16,4,4,4,4,4,4,4,4,4,4,4,16
endlayer

layer
16,16,16,16,16,16,16,16,16,16,16,16,16
16,16,5,5,5,5,5,5,5,5,5,16,16
16,5,5,6,6,6,6,6,6,6,5,5,16
16,5,6,2,2,2,2,2,2,2,6,5,16
16,5,6,2,2,2,2,2,2,2,6,5,16
16,5,6,2,2,2,2,2,2,2,6,5,16
16,5,6,2,2,2,17,2,2,2,6,5,16
16,5,6,2,2,2,2,2,2,2,6,5,16
16,5,6,2,2,2,2,2,2,2,6,5,16
16,5,6,2,2,2,2,2,2,2,6,5,16
16,5,5,6,6,6,6,6,6,6,5,5,16
16,16,5,5,5,5,5,5,5,5,5,16,16
16,16,16,16,16,16,16,16,16,16,16,16,16
endlayer

layer
16,16,16,16,16,16,16,16,16,16,16,16,16
16,16,5,5,5,5,5,5,5,5,5,16,16
16,5,5,6,6,6,6,6,6,6,5,5,16
16,5,6,2,2,2,2,2,2,2,6,5,16
16,5,6,2,2,2,2,2,2,2,6,5,16
16,5,6,2,2,2,2,2,2,2,6,5,16
16,5,6,2,2,2,17,2,2,2,6,5,16
16,5,6,2,2,2,2,2,2,2,6,5,16
16,5,6,2,2,2,2,2,2,2,6,5,16
16,5,6,2,2,2,2,2,2,2,6,5,16
16,5,5,6,6,6,6,6,6,6,5,5,16
16,16,5,5,5,5,5,5,5,5,5,16,16
16,16,16,16,16,16,16,16,16,16,16,16,16
endlayer

layer
16,16,16,16,16,16,16,16,16,16,16,16,16
16,16,5,5,5,5,5,5,5,5,5,16,16
16,5,5,6,6,6,6,6,6,6,5,5,16
16,5,6,2,2,2,2,2,2,2,6,5,16
16,5,6,2,2,2,2,2,2,2,6,5,16
16,5,6,2,2,2,2,2,2,2,6,5,16
16,5,6,2,2,2,17,2,2,2,6,5,16
16,5,6,2,2,2,2,2,2,2,6,5,16
16,5,6,2,2,2,2,2,2,2,6,5,16
16,5,6,2,2,2,2,2,2,2,6,5,16
16,5,5,6,6,6,6,6,6,6,5,5,16
16,16,5,5,5,5,5,5,5,5,5,16,16
16,16,16,16,16,16,16,16,16,16,16,16,16
endlayer

layer
16,16,16,16,16,16,16,16,16,16,16,16,16
16,16,5,5,5,5,5,5,5,5,5,16,16
16,5,5,6,6,6,6,6,6,6,5,5,16
16,5,6,2,2,2,2,2,2,2,6,5,16
16,5,6,2,2,2,2,2,2,2,6,5,16
16,5,6,2,2,2,2,2,2,2,6,5,16
16,5,6,2,2,2,17,2,2,2,6,5,16
16,5,6,2,2,2,2,2,2,2,6,5,16
16,5,6,2,2,2,2,2,2,2,6,5,16
16,5,6,2,2,2,2,2,2,2,6,5,16
16,5,5,6,6,6,6,6,6,6,5,5,16
16,16,5,5,5,5,5,5,5,5,5,16,16
16,16,16,16,16,16,16,16,16,16,16,16,16
endlayer

layer
16,16,16,16,16,16,16,16,16,16,16,16,16
16,16,5,5,5,5,5,5,5,5,5,16,16
16,5,5,3,3,3,3,3,3,3,5,5,16
16,5,3,3,2,2,2,2,2,3,3,5,16
16,5,3,2,2,2,2,2,2,2,3,5,16
16,5,3,2,2,2,2,2,2,2,3,5,16
16,5,3,2,2,2,17,2,2,2,3,5,16
16,5,3,2,2,2,2,2,2,2,3,5,16
16,5,3,2,2,2,2,2,2,2,3,5,16
16,5,3,3,2,2,2,2,2,3,3,5,16
16,5,5,3,3,3,3,3,3,3,5,5,16
16,16,5,5,5,5,5,5,5,5,5,16,16
16,16,16,16,16,16,16,16,16,16,16,16,16
endlayer

layer
16,16,16,16,16,16,16,16,16,16,16,16,16
16,16,16,16,16,16,16,16,16,16,16,16,16
16,16,16,7,7,7,7,7,7,7,16,16,16
16,16,7,7,8,8,8,8,8,7,7,16,16
16,16,7,8,2,2,2,2,2,8,7,16,16
16,16,7,8,2,2,2,2,2,8,7,16,16
16,16,7,8,2,2,17,2,2,8,7,16,16
16,16,7,8,2,2,2,2,2,8,7,16,16
16,16,7,8,2,2,2,2,2,8,7,16,16
16,16,7,7,8,8,8,8,8,7,7,16,16
16,16,16,7,7,7,7,7,7,7,16,16,16
16,16,16,16,16,16,16,16,16,16,16,16,16
16,16,16,16,16,16,16,16,16,16,16,16,16
endlayer

layer
16,16,16,16,16,16,16,16,16,16,16,16,16
16,16,16,16,16,16,16,16,16,16,16,16,16
16,16,16,7,7,7,7,7,7,7,16,16,16
16,16,7,7,8,8,8,8,8,7,7,16,16
16,16,7,8,2,2,2,2,2,8,7,16,16
16,16,7,8,2,2,2,2,2,8,7,16,16
16,16,7,8,2,2,17,2,2,8,7,16,16
16,16,7,8,2,2,2,2,2,8,7,16,16
16,16,7,8,2,2,2,2,2,8,7,16,16
16,16,7,7,8,8,8,8,8,7,7,16,16
16,16,16,7,7,7,7,7,7,7,16,16,16
16,16,16,16,16,16,16,16,16,16,16,16,16
16,16,16,16,16,16,16,16,16,16,16,16,16
endlayer

layer
16,16,16,16,16,16,16,16,16,16,16,16,16
16,16,16,16,16,16,16,16,16,16,16,16,16
16,16,16,7,7,7,7,7,7,7,16,16,16
16,16,7,7,8,8,8,8,8,7,7,16,16
16,16,7,8,2,2,2,2,2,8,7,16,16
16,16,7,8,2,2,2,2,2,8,7,16,16
16,16,7,8,2,2,17,2,2,8,7,16,16
16,16,7,8,2,2,2,2,2,8,7,16,16
16,16,7,8,2,2,2,2,2,8,7,16,16
16,16,7,7,8,8,8,8,8,7,7,16,16
16,16,16,7,7,7,7,7,7,7,16,16,16
16,16,16,16,16,16,16,16,16,16,16,16,16
16,16,16,16,16,16,16,16,16,16,16,16,16
endlayer

layer
16,16,16,16,16,16,16,16,16,16,16,16,16
16,16,16,16,16,16,16,16,16,16,16,16,16
16,16,16,7,7,7,7,7,7,7,16,16,16
16,16,7,7,8,8,8,8,8,7,7,16,16
16,16,7,8,2,2,2,2,2,8,7,16,16
16,16,7,8,2,2,2,2,2,8,7,16,16
16,16,7,8,2,2,17,2,2,8,7,16,16
16,16,7,8,2,2,2,2,2,8,7,16,16
16,16,7,8,2,2,2,2,2,8,7,16,16
16,16,7,7,8,8,8,8,8,7,7,16,16
16,16,16,7,7,7,7,7,7,7,16,16,16
16,16,16,16,16,16,16,16,16,16,16,16,16
16,16,16,16,16,16,16,16,16,16,16,16,16
endlayer

layer
16,16,16,16,16,16,16,16,16,16,16,16,16
16,16,16,16,16,16,16,16,16,16,16,16,16
16,16,16,7,7,7,7,7,7,7,16,16,16
16,16,7,7,3,3,3,3,3,7,7,16,16
16,16,7,3,3,2,2,2,3,3,7,16,16
16,16,7,3,2,2,2,2,2,3,7,16,16
16,16,7,3,2,2,17,2,2,3,7,16,16
16,16,7,3,2,2,2,2,2,3,7,16,16
16,16,7,3,3,2,2,2,3,3,7,16,16
16,16,7,7,3,3,3,3,3,7,7,16,16
16,16,16,7,7,7,7,7,7,7,16,16,16
16,16,16,16,16,16,16,16,16,16,16,16,16
16,16,16,16,16,16,16,16,16,16,16,16,16
endlayer

layer
16,16,16,16,16,16,16,16,16,16,16,16,16
16,16,16,16,16,16,16,16,16,16,16,16,16
16,16,16,16,16,16,16,16,16,16,16,16,16
16,16,16,16,9,9,9,9,9,16,16,16,16
16,16,16,9,9,10,10,10,9,9,16,16,16
16,16,16,9,10,2,2,2,10,9,16,16,16
16,16,16,9,10,2,17,2,10,9,16,16,16
16,16,16,9,10,2,2,2,10,9,16,16,16
16,16,16,9,9,10,10,10,9,9,16,16,16
16,16,16,16,9,9,9,9,9,16,16,16,16
16,16,16,16,16,16,16,16,16,16,16,16,16
16,16,16,16,16,16,16,16,16,16,16,16,16
16,16,16,16,16,16,16,16,16,16,16,16,16
endlayer

layer
16,16,16,16,16,16,16,16,16,16,16,16,16
16,16,16,16,16,16,16,16,16,16,16,16,16
16,16,16,16,16,16,16,16,16,16,16,16,16
16,16,16,16,9,9,9,9,9,16,16,16,16
16,16,16,9,9,10,10,10,9,9,16,16,16
16,16,16,9,10,2,2,2,10,9,16,16,16
16,16,16,9,10,2,17,2,10,9,16,16,16
16,16,16,9,10,2,2,2,10,9,16,16,16
16,16,16,9,9,10,10,10,9,9,16,16,16
16,16,16,16,9,9,9,9,9,16,16,16,16
16,16,16,16,16,16,16,16,16,16,16,16,16
16,16,16,16,16,16,16,16,16,16,16,16,16
16,16,16,16,16,16,16,16,16,16,16,16,16
endlayer

layer
16,16,16,16,16,16,16,16,16,16,16,16,16
16,16,16,16,16,16,16,16,16,16,16,16,16
16,16,16,16,16,16,16,16,16,16,16,16,16
16,16,16,16,9,9,9,9,9,16,16,16,16
16,16,16,9,9,10,10,10,9,9,16,16,16
16,16,16,9,10,2,2,2,10,9,16,16,16
16,16,16,9,10,2,17,2,10,9,16,16,16
16,16,16,9,10,2,2,2,10,9,16,16,16
16,16,16,9,9,10,10,10,9,9,16,16,16
16,16,16,16,9,9,9,9,9,16,16,16,16
16,16,16,16,16,16,16,16,16,16,16,16,16
16,16,16,16,16,16,16,16,16,16,16,16,16
16,16,16,16,16,16,16,16,16,16,16,16,16
endlayer

layer
16,16,16,16,16,16,16,16,16,16,16,16,16
16,16,16,16,16,16,16,16,16,16,16,16,16
16,16,16,16,16,16,16,16,16,16,16,16,16
16,16,16,16,9,9,9,9,9,16,16,16,16
16,16,16,9,9,10,10,10,9,9,16,16,16
16,16,16,9,10,2,2,2,10,9,16,16,16
16,16,16,9,10,2,17,2,10,9,16,16,16
16,16,16,9,10,2,2,2,10,9,16,16,16
16,16,16,9,9,10,10,10,9,9,16,16,16
16,16,16,16,9,9,9,9,9,16,16,16,16
16,16,16,16,16,16,16,16,16,16,16,16,16
16,16,16,16,16,16,16,16,16,16,16,16,16
16,16,16,16,16,16,16,16,16,16,16,16,16
endlayer

layer
16,16,16,16,16,16,16,16,16,16,16,16,16
16,16,16,16,16,16,16,16,16,16,16,16,16
16,16,16,16,16,16,16,16,16,16,16,16,16
16,16,16,16,9,9,9,9,9,16,16,16,16
16,16,16,9,9,3,3,3,9,9,16,16,16
16,16,16,9,3,3,2,3,3,9,16,16,16
16,16,16,9,3,2,2,2,3,9,16,16,16
16,16,16,9,3,3,2,3,3,9,16,16,16
16,16,16,9,9,3,3,3,9,9,16,16,16
16,16,16,16,9,9,9,9,9,16,16,16,16
16,16,16,16,16,16,16,16,16,16,16,16,16
16,16,16,16,16,16,16,16,16,16,16,16,16
16,16,16,16,16,16,16,16,16,16,16,16,16
endlayer

layer
16,16,16,16,16,16,16,16,16,16,16,16,16
16,16,16,16,16,16,16,16,16,16,16,16,16
16,16,16,16,16,16,16,16,16,16,16,16,16
16,16,16,16,16,16,16,16,16,16,16,16,16
16,16,16,16,16,11,11,11,16,16,16,16,16
16,16,16,16,11,11,12,11,11,16,16,16,16
16,16,16,16,11,12,2,12,11,16,16,16,16
16,16,16,16,11,11,12,11,11,16,16,16,16
16,16,16,16,16,11,11,11,16,16,16,16,16
16,16,16,16,16,16,16,16,16,16,16,16,16
16,16,16,16,16,16,16,16,16,16,16,16,16
16,16,16,16,16,16,16,16,16,16,16,16,16
16,16,16,16,16,16,16,16,16,16,16,16,16
endlayer

layer
16,16,16,16,16,16,16,16,16,16,16,16,16
16,16,16,16,16,16,16,16,16,16,16,16,16
16,16,16,16,16,16,16,16,16,16,16,16,16
16,16,16,16,16,16,16,16,16,16,16,16,16
16,16,16,16,16,11,11,11,16,16,16,16,16
16,16,16,16,11,11,12,11,11,16,16,16,16
16,16,16,16,11,12,2,12,11,16,16,16,16
16,16,16,16,11,11,12,11,11,16,16,16,16
16,16,16,16,16,11,11,11,16,16,16,16,16
16,16,16,16,16,16,16,16,16,16,16,16,16
16,16,16,16,16,16,16,16,16,16,16,16,16
16,16,16,16,16,16,16,16,16,16,16,16,16
16,16,16,16,16,16,16,16,16,16,16,16,16
endlayer

layer
16,16,16,16,16,16,16,16,16,16,16,16,16
16,16,16,16,16,16,16,16,16,16,16,16,16
16,16,16,16,16,16,16,16,16,16,16,16,16
16,16,16,16,16,16,16,16,16,16,16,16,16
16,16,16,16,16,11,11,11,16,16,16,16,16
16,16,16,16,11,11,12,11,11,16,16,16,16
16,16,16,16,11,12,2,12,11,16,16,16,16
16,16,16,16,11,11,12,11,11,16,16,16,16
16,16,16,16,16,11,11,11,16,16,16,16,16
16,16,16,16,16,16,16,16,16,16,16,16,16
16,16,16,16,16,16,16,16,16,16,16,16,16
16,16,16,16,16,16,16,16,16,16,16,16,16
16,16,16,16,16,16,16,16,16,16,16,16,16
endlayer

layer
16,16,16,16,16,16,16,16,16,16,16,16,16
16,16,16,16,16,16,16,16,16,16,16,16,16
16,16,16,16,16,16,16,16,16,16,16,16,16
16,16,16,16,16,16,16,16,16,16,16,16,16
16,16,16,16,16,11,11,11,16,16,16,16,16
16,16,16,16,11,11,12,11,11,16,16,16,16
16,16,16,16,11,12,2,12,11,16,16,16,16
16,16,16,16,11,11,12,11,11,16,16,16,16
16,16,16,16,16,11,11,11,16,16,16,16,16
16,16,16,16,16,16,16,16,16,16,16,16,16
16,16,16,16,16,16,16,16,16,16,16,16,16
16,16,16,16,16,16,16,16,16,16,16,16,16
16,16,16,16,16,16,16,16,16,16,16,16,16
endlayer

layer
16,16,16,16,16,16,16,16,16,16,16,16,16
16,16,16,16,16,16,16,16,16,16,16,16,16
16,16,16,16,16,16,16,16,16,16,16,16,16
16,16,16,16,16,16,16,16,16,16,16,16,16
16,16,16,16,16,11,11,11,16,16,16,16,16
16,16,16,16,11,3,3,3,11,16,16,16,16
16,16,16,16,11,3,2,3,11,16,16,16,16
16,16,16,16,11,3,3,3,11,16,16,16,16
16,16,16,16,16,11,11,11,16,16,16,16,16
16,16,16,16,16,16,16,16,16,16,16,16,16
16,16,16,16,16,16,16,16,16,16,16,16,16
16,16,16,16,16,16,16,16,16,16,16,16,16
16,16,16,16,16,16,16,16,16,16,16,16,16
endlayer

layer
16,16,16,16,16,16,16,16,16,16,16,16,16
16,16,16,16,16,16,16,16,16,16,16,16,16
16,16,16,16,16,16,16,16,16,16,16,16,16
16,16,16,16,16,16,16,16,16,16,16,16,16
16,16,16,16,16,16,16,16,16,16,16,16,16
16,16,16,16,16,13,13,13,16,16,16,16,16
16,16,16,16,16,13,14,13,16,16,16,16,16
16,16,16,16,16,13,13,13,16,16,16,16,16
16,16,16,16,16,16,16,16,16,16,16,16,16
16,16,16,16,16,16,16,16,16,16,16,16,16
16,16,16,16,16,16,16,16,16,16,16,16,16
16,16,16,16,16,16,16,16,16,16,16,16,16
16,16,16,16,16,16,16,16,16,16,16,16,16
endlayer

layer
16,16,16,16,16,16,16,16,16,16,16,16,16
16,16,16,16,16,16,16,16,16,16,16,16,16
16,16,16,16,16,16,16,16,16,16,16,16,16
16,16,16,16,16,16,16,16,16,16,16,16,16
16,16,16,16,16,16,16,16,16,16,16,16,16
16,16,16,16,16,13,13,13,16,16,16,16,16
16,16,16,16,16,13,14,13,16,16,16,16,16
16,16,16,16,16,13,13,13,16,16,16,16,16
16,16,16,16,16,16,16,16,16,16,16,16,16
16,16,16,16,16,16,16,16,16,16,16,16,16
16,16,16,16,16,16,16,16,16,16,16,16,16
16,16,16,16,16,16,16,16,16,16,16,16,16
16,16,16,16,16,16,16,16,16,16,16,16,16
endlayer

layer
16,16,16,16,16,16,16,16,16,16,16,16,16
16,16,16,16,16,16,16,16,16,16,16,16,16
16,16,16,16,16,16,16,16,16,16,16,16,16
16,16,16,16,16,16,16,16,16,16,16,16,16
16,16,16,16,16,16,16,16,16,16,16,16,16
16,16,16,16,16,13,13,13,16,16,16,16,16
16,16,16,16,16,13,14,13,16,16,16,16,16
16,16,16,16,16,13,13,13,16,16,16,16,16
16,16,16,16,16,16,16,16,16,16,16,16,16
16,16,16,16,16,16,16,16,16,16,16,16,16
16,16,16,16,16,16,16,16,16,16,16,16,16
16,16,16,16,16,16,16,16,16,16,16,16,16
16,16,16,16,16,16,16,16,16,16,16,16,16
endlayer

layer
16,16,16,16,16,16,16,16,16,16,16,16,16
16,16,16,16,16,16,16,16,16,16,16,16,16
16,16,16,16,16,16,16,16,16,16,16,16,16
16,16,16,16,16,16,16,16,16,16,16,16,16
16,16,16,16,16,16,16,16,16,16,16,16,16
16,16,16,16,16,13,13,13,16,16,16,16,16
16,16,16,16,16,13,14,13,16,16,16,16,16
16,16,16,16,16,13,13,13,16,16,16,16,16
16,16,16,16,16,16,16,16,16,16,16,16,16
16,16,16,16,16,16,16,16,16,16,16,16,16
16,16,16,16,16,16,16,16,16,16,16,16,16
16,16,16,16,16,16,16,16,16,16,16,16,16
16,16,16,16,16,16,16,16,16,16,16,16,16
endlayer

layer
16,16,16,16,16,16,16,16,16,16,16,16,16
16,16,16,16,16,16,16,16,16,16,16,16,16
16,16,16,16,16,16,16,16,16,16,16,16,16
16,16,16,16,16,16,16,16,16,16,16,16,16
16,16,16,16,16,16,16,16,16,16,16,16,16
16,16,16,16,16,13,13,13,16,16,16,16,16
16,16,16,16,16,13,14,13,16,16,16,16,16
16,16,16,16,16,13,13,13,16,16,16,16,16
16,16,16,16,16,16,16,16,16,16,16,16,16
16,16,16,16,16,16,16,16,16,16,16,16,16
16,16,16,16,16,16,16,16,16,16,16,16,16
16,16,16,16,16,16,16,16,16,16,16,16,16
16,16,16,16,16,16,16,16,16,16,16,16,16
endlayer

layer
16,16,16,16,16,16,16,16,16,16,16,16,16
16,16,16,16,16,16,16,16,16,16,16,16,16
16,16,16,16,16,16,16,16,16,16,16,16,16
16,16,16,16,16,16,16,16,16,16,16,16,16
16,16,16,16,16,16,16,16,16,16,16,16,16
16,16,16,16,16,15,15,15,16,16,16,16,16
16,16,16,16,16,15,15,15,16,16,16,16,16
16,16,16,16,16,15,15,15,16,16,16,16,16
16,16,16,16,16,16,16,16,16,16,16,16,16
16,16,16,16,16,16,16,16,16,16,16,16,16
16,16,16,16,16,16,16,16,16,16,16,16,16
16,16,16,16,16,16,16,16,16,16,16,16,16
16,16,16,16,16,16,16,16,16,16,16,16,16
endlayer

layer
16,16,16,16,16,16,16,16,16,16,16,16,16
16,16,16,16,16,16,16,16,16,16,16,16,16
16,16,16,16,16,16,16,16,16,16,16,16,16
16,16,16,16,16,16,16,16,16,16,16,16,16
16,16,16,16,16,16,16,16,16,16,16,16,16
16,16,16,16,16,16,16,16,16,16,16,16,16
16,16,16,16,16,16,15,16,16,16,16,16,16
16,16,16,16,16,16,16,16,16,16,16,16,16
16,16,16,16,16,16,16,16,16,16,16,16,16
16,16,16,16,16,16,16,16,16,16,16,16,16
16,16,16,16,16,16,16,16,16,16,16,16,16
16,16,16,16,16,16,16,16,16,16,16,16,16
16,16,16,16,16,16,16,16,16,16,16,16,16
endlayer

